sample_logs/sample_log_8.log
[Sun, 23 Jan 2000 01:23:45 GMT] 1 CREATE "LIMIT_ORDER_BUY 100 200"
[Sun, 23 Jan 2000 01:23:46 GMT] 2 CREATE "LIMIT_ORDER_BUY 101 200"
[Sun, 23 Jan 2000 01:23:47 GMT] 3 CREATE "LIMIT_ORDER_BUY 102 200"
[Sun, 23 Jan 2000 01:23:48 GMT] 4 CREATE "LIMIT_ORDER_BUY 103 200"
[Sun, 23 Jan 2000 01:23:49 GMT] 5 CREATE "LIMIT_ORDER_BUY 104 200"
[Sun, 23 Jan 2000 01:23:50 GMT] 6 CREATE "LIMIT_ORDER_BUY 105 200"
[Sun, 23 Jan 2000 01:23:51 GMT] 6 CANCEL "EMPTY"
[Sun, 23 Jan 2000 01:23:51 GMT] 7 CREATE "LIMIT_ORDER_SELL 104 100"
