sample_logs/sample_log_9.log
[Sun, 23 Jan 2000 01:23:45 GMT] 1 CREATE "LIMIT_ORDER_BUY 100 200"
[Sun, 23 Jan 2000 01:23:46 GMT] 2 CREATE "LIMIT_ORDER_SELL 98 100"
[Sun, 23 Jan 2000 01:23:47 GMT] 3 CREATE "LIMIT_ORDER_BUY 97 200"
[Sun, 23 Jan 2000 01:23:48 GMT] 4 CREATE "LIMIT_ORDER_SELL 99 100"
[Sun, 23 Jan 2000 01:23:49 GMT] 3 REPLACE "LIMIT_ORDER_BUY 97 400"
[Sun, 23 Jan 2000 01:23:50 GMT] 3 CANCEL "EMPTY"
[Sun, 23 Jan 2000 01:23:51 GMT] 5 CREATE "LIMIT_ORDER_SELL 97 300"
[Sun, 23 Jan 2000 01:23:52 GMT] 6 CREATE "LIMIT_ORDER_BUY 97 400"
[Sun, 23 Jan 2000 01:23:53 GMT] 7 CREATE "LIMIT_ORDER_BUY 98 500"
[Sun, 23 Jan 2000 01:23:54 GMT] 6 REPLACE "LIMIT_ORDER_BUY 97 600"
[Sun, 23 Jan 2000 01:23:55 GMT] 8 CREATE "LIMIT_ORDER_SELL 98 600"
[Sun, 23 Jan 2000 01:23:56 GMT] 6 CANCEL "EMPTY"
[Sun, 23 Jan 2000 01:23:57 GMT] 9 CREATE "LIMIT_ORDER_SELL 97 500"
[Sun, 23 Jan 2000 01:23:58 GMT] 10 CREATE "LIMIT_ORDER_SELL 96 500"
[Sun, 23 Jan 2000 01:23:59 GMT] 11 CREATE "LIMIT_ORDER_SELL 97 500"
[Sun, 23 Jan 2000 01:24:00 GMT] 12 CREATE "LIMIT_ORDER_BUY 97 2000"
